Workbook

Sheet Cover
B2: AI Chip Company — DCF Valuation Model
B4: Discounted Cash Flow Valuation with Bear / Base / Bull Scenarios
B6: Model Overview
B7: Subject | C7: Hypothetical AI Chip Company (NVIDIA-like profile)
B8: Base Year | C8: FY2024 (Actual)
B9: Forecast Horizon | C9: FY2025E – FY2029E (5-year explicit) + Terminal
B10: Base Case CAGR | C10: 25% (5-year revenue CAGR, per requirement)
B11: Scenarios | C11: Bear (12% CAGR) / Base (25%) / Bull (40%)
B12: Valuation Methods | C12: DCF (Gordon Growth) + Exit EV/EBITDA Multiple cross-check
B13: Sensitivities | C13: WACC × Terminal Growth ; Exit Multiple × WACC
B14: Currency | C14: USD, $ Millions (unless noted)
B16: Sheet Navigation
B17: Assumptions | C17: All input drivers for Bear / Base / Bull scenarios
B18: Bear_Case | C18: Full DCF: P&L → FCF → WACC → Enterprise/Equity Value
B19: Base_Case | C19: Full DCF (Base case: 25% revenue CAGR)
B20: Bull_Case | C20: Full DCF (Bull case: 40% revenue CAGR)
B21: Scenario_Summary | C21: Side-by-side comparison of three scenarios
B22: WACC_Sensitivity | C22: Two-way data table: WACC × Terminal Growth Rate
B23: TV_Sensitivity | C23: Two-way data table: Exit EV/EBITDA × WACC
B25: Color Legend (IB Convention)
B26: Hard-coded input
B27: Formula (same sheet)
B28: Cross-sheet link
B29: Key assumption
B31: Disclaimer: This model is for educational and illustrative purposes only. Base-year figures are hypothetical (NVIDIA-like profile) and do not constitute investment advice. All projections are subject to significant uncertainty.

Sheet Assumptions
B2: Assumptions — Bear / Base / Bull
B4: Driver | C4: Bear | D4: Base | E4: Bull | F4: Unit | G4: Notes
B5: Scenario description | C5: AI capex slowdown, hyperscaler digestion, China export restrictions bite | D5: Sustained AI demand, broad enterprise adoption, stable competitive moat | E5: AI supercycle, AGI inflection, monopoly-like pricing power | F5: —
B7: Revenue Drivers
B8: Base year revenue (FY2024A) | C8: 60900 | D8: 60900 | E8: 60900 | F8: $M | G8: Hypothetical; NVIDIA-like profile
B9: 5-year revenue CAGR | C9: 0.12 | D9: 0.25 | E9: 0.4 | F9: % | G9: Base = 25% per user requirement
B10: Terminal revenue growth (g) | C10: 0.025 | D10: 0.03 | E10: 0.035 | F10: % | G10: Perpetuity growth, kept below long-run GDP
B12: Margin & Cost Drivers
B13: Gross margin — Year 1 | C13: 0.58 | D13: 0.68 | E13: 0.74 | F13: %;(%);"-"
B14: Gross margin — Year 5 | C14: 0.62 | D14: 0.72 | E14: 0.78 | F14: %;(%);"-"
B15: OpEx % of revenue — Year 1 | C15: 0.22 | D15: 0.18 | E15: 0.15 | F15: %;(%);"-"
B16: OpEx % of revenue — Year 5 | C16: 0.18 | D16: 0.14 | E16: 0.11 | F16: %;(%);"-"
B17: CapEx % of revenue | C17: 0.07 | D17: 0.06 | E17: 0.05 | F17: %;(%);"-"
B18: Δ NWC % of revenue | C18: 0.08 | D18: 0.06 | E18: 0.05 | F18: %;(%);"-"
B19: Effective tax rate | C19: 0.21 | D19: 0.21 | E19: 0.21 | F19: %;(%);"-"
B21: WACC Components
B22: Risk-free rate (10Y UST) | C22: 0.045 | D22: 0.042 | E22: 0.04 | F22: % | G22: 10-yr US Treasury yield
B23: Equity risk premium | C23: 0.06 | D23: 0.055 | E23: 0.05 | F23: % | G23: Damodaran implied ERP
B24: Levered beta | C24: 1.55 | D24: 1.35 | E24: 1.15 | F24: x | G24: Semi industry beta, 2-yr weekly
B25: Pre-tax cost of debt | C25: 0.055 | D25: 0.05 | E25: 0.045 | F25: % | G25: Investment-grade credit
B26: Target D/(D+E) | C26: 0.1 | D26: 0.1 | E26: 0.1 | F26: % | G26: Modest leverage
B27: Effective tax rate (for WACC) | C27: 0.21 | D27: 0.21 | E27: 0.21 | F27: % | G27: Same as operating tax
B28: WACC (computed) | C28: =(1-C26)*(C22+C24*C23)+C26*C25*(1-C27) | D28: =(1-D26)*(D22+D24*D23)+D26*D25*(1-D27) | E28: =(1-E26)*(E22+E24*E23)+E26*E25*(1-E27) | F28: % | G28: Weighted average cost of capital
B30: Terminal Value Inputs
B31: Terminal growth rate (g) | C31: 0.025 | D31: 0.03 | E31: 0.035 | G31: Perpetuity growth
B32: Exit EV/EBITDA multiple | C32: 16 | D32: 20 | E32: 25 | G32: Cross-check method
B34: Capital Structure & Share Count
B35: Total debt (FY2024A) | C35: 8500 | D35: 8500 | E35: 8500 | F35: $M
B36: Cash & equivalents (FY2024A) | C36: 26000 | D36: 26000 | E36: 26000 | F36: $M
B37: Shares outstanding | C37: 24600 | D37: 24600 | E37: 24600 | F37: M shares
B38: Current share price (illustrative) | C38: 135 | D38: 135 | E38: 135 | F38: $/share

Sheet Bear_Case
B2: Bear Case — DCF Valuation
B3: Scenario: Bear | 5-yr CAGR: 12% | WACC: 11.5% | AI capex slowdown, hyperscaler digestion, China export restrictions bite
C4: FY2024A | D4: FY2025E | E4: FY2026E | F4: FY2027E | G4: FY2028E | H4: FY2029E | I4: FY2030E
B6: 1. Revenue Build
B7: Revenue ($M) | C7: =Assumptions!C8 | D7: =C7*(1+Assumptions!$C$9) | E7: =D7*(1+Assumptions!$C$9) | F7: =E7*(1+Assumptions!$C$9) | G7: =F7*(1+Assumptions!$C$9) | H7: =G7*(1+Assumptions!$C$9) | I7: =H7*(1+Assumptions!C10)
B8: YoY growth | C8: — | D8: =IFERROR(D7/C7-1,0) | E8: =IFERROR(E7/D7-1,0) | F8: =IFERROR(F7/E7-1,0) | G8: =IFERROR(G7/F7-1,0) | H8: =IFERROR(H7/G7-1,0) | I8: =IFERROR(I7/H7-1,0)
B10: 2. Income Statement
B11: Gross profit ($M) | C11: 44300 | D11: =D7*(Assumptions!$C$13+(Assumptions!$C$14-Assumptions!$C$13)*0.0) | E11: =E7*(Assumptions!$C$13+(Assumptions!$C$14-Assumptions!$C$13)*0.25) | F11: =F7*(Assumptions!$C$13+(Assumptions!$C$14-Assumptions!$C$13)*0.5) | G11: =G7*(Assumptions!$C$13+(Assumptions!$C$14-Assumptions!$C$13)*0.75) | H11: =H7*(Assumptions!$C$13+(Assumptions!$C$14-Assumptions!$C$13)*1.0) | I11: =I7*Assumptions!$C$14
B12: Gross margin % | C12: =IFERROR(C11/C7,0) | D12: =IFERROR(D11/D7,0) | E12: =IFERROR(E11/E7,0) | F12: =IFERROR(F11/F7,0) | G12: =IFERROR(G11/G7,0) | H12: =IFERROR(H11/H7,0) | I12: =IFERROR(I11/I7,0)
B13: Operating expenses ($M) | C13: 11600 | D13: =D7*(Assumptions!$C$15+(Assumptions!$C$16-Assumptions!$C$15)*0.0) | E13: =E7*(Assumptions!$C$15+(Assumptions!$C$16-Assumptions!$C$15)*0.25) | F13: =F7*(Assumptions!$C$15+(Assumptions!$C$16-Assumptions!$C$15)*0.5) | G13: =G7*(Assumptions!$C$15+(Assumptions!$C$16-Assumptions!$C$15)*0.75) | H13: =H7*(Assumptions!$C$15+(Assumptions!$C$16-Assumptions!$C$15)*1.0) | I13: =I7*Assumptions!$C$16
B14: EBITDA ($M) | C14: =C11-C13 | D14: =D11-D13 | E14: =E11-E13 | F14: =F11-F13 | G14: =G11-G13 | H14: =H11-H13 | I14: =I11-I13
B15: EBITDA margin % | C15: =IFERROR(C14/C7,0) | D15: =IFERROR(D14/D7,0) | E15: =IFERROR(E14/E7,0) | F15: =IFERROR(F14/F7,0) | G15: =IFERROR(G14/G7,0) | H15: =IFERROR(H14/H7,0) | I15: =IFERROR(I14/I7,0)
B16: Depreciation & amortization ($M) | C16: 2800 | D16: =D7*0.045 | E16: =E7*0.045 | F16: =F7*0.045 | G16: =G7*0.045 | H16: =H7*0.045 | I16: =I7*0.045
B17: EBIT ($M) | C17: =C14-C16 | D17: =D14-D16 | E17: =E14-E16 | F17: =F14-F16 | G17: =G14-G16 | H17: =H14-H16 | I17: =I14-I16
B18: EBIT margin % | C18: =IFERROR(C17/C7,0) | D18: =IFERROR(D17/D7,0) | E18: =IFERROR(E17/E7,0) | F18: =IFERROR(F17/F7,0) | G18: =IFERROR(G17/G7,0) | H18: =IFERROR(H17/H7,0) | I18: =IFERROR(I17/I7,0)
B19: Taxes ($M) | C19: 6300 | D19: =MAX(0,D17)*Assumptions!$C$19 | E19: =MAX(0,E17)*Assumptions!$C$19 | F19: =MAX(0,F17)*Assumptions!$C$19 | G19: =MAX(0,G17)*Assumptions!$C$19 | H19: =MAX(0,H17)*Assumptions!$C$19 | I19: =MAX(0,I17)*Assumptions!$C$19
B20: NOPAT ($M) | C20: =C17-C19 | D20: =D17-D19 | E20: =E17-E19 | F20: =F17-F19 | G20: =G17-G19 | H20: =H17-H19 | I20: =I17-I19
B22: 3. Unlevered Free Cash Flow Build
B23: NOPAT ($M) | C23: =C20 | D23: =D20 | E23: =E20 | F23: =F20 | G23: =G20 | H23: =H20 | I23: =I20
B24: (+) D&A | C24: =C16 | D24: =D16 | E24: =E16 | F24: =F16 | G24: =G16 | H24: =H16 | I24: =I16
B25: (–) Capital expenditures | C25: 3200 | D25: =D7*Assumptions!$C$17 | E25: =E7*Assumptions!$C$17 | F25: =F7*Assumptions!$C$17 | G25: =G7*Assumptions!$C$17 | H25: =H7*Assumptions!$C$17 | I25: =I7*Assumptions!$C$17
B26: (–) Δ Net working capital | C26: 0 | D26: =(D7-C7)*Assumptions!$C$18 | E26: =(E7-D7)*Assumptions!$C$18 | F26: =(F7-E7)*Assumptions!$C$18 | G26: =(G7-F7)*Assumptions!$C$18 | H26: =(H7-G7)*Assumptions!$C$18 | I26: =(I7-H7)*Assumptions!$C$18
B27: Unlevered Free Cash Flow ($M) | C27: =C23+C24-C25-C26 | D27: =D23+D24-D25-D26 | E27: =E23+E24-E25-E26 | F27: =F23+F24-F25-F26 | G27: =G23+G24-G25-G26 | H27: =H23+H24-H25-H26 | I27: =I23+I24-I25-I26
B28: FCF margin % | C28: =IFERROR(C27/C7,0) | D28: =IFERROR(D27/D7,0) | E28: =IFERROR(E27/E7,0) | F28: =IFERROR(F27/F7,0) | G28: =IFERROR(G27/G7,0) | H28: =IFERROR(H27/H7,0) | I28: =IFERROR(I27/I7,0)
B30: 4. WACC & Discounting
B31: WACC | C31: — | D31: =Assumptions!$C$28 | E31: =Assumptions!$C$28 | F31: =Assumptions!$C$28 | G31: =Assumptions!$C$28 | H31: =Assumptions!$C$28 | I31: =Assumptions!$C$28
B32: Discount period (yrs, mid-year) | C32: — | D32: =1-0.5 | E32: =2-0.5 | F32: =3-0.5 | G32: =4-0.5 | H32: =5-0.5 | I32: —
B33: Discount factor | D33: =1/(1+D31)^D32 | E33: =1/(1+E31)^E32 | F33: =1/(1+F31)^F32 | G33: =1/(1+G31)^G32 | H33: =1/(1+H31)^H32
B34: PV of unlevered FCF ($M) | D34: =D27*D33 | E34: =E27*E33 | F34: =F27*F33 | G34: =G27*G33 | H34: =H27*H33
B35: Sum PV of explicit FCF ($M) | C35: =SUM(D34:H34)
B37: 5. Terminal Value
B38: Terminal Year EBITDA ($M) | C38: — | H38: =H14
B39: Terminal year FCF ($M) | C39: — | H39: =H27
B40: Terminal growth rate (g) | C40: — | H40: =Assumptions!C10
B41: WACC – g | C41: — | H41: =H31-H40
B42: Terminal Value (Gordon) ($M) | H42: =H27*(1+H40)/(H31-H40)
B43: PV of Terminal Value ($M) | H43: =H42*H33
B45: Exit EV/EBITDA multiple (x) | C45: — | H45: =Assumptions!C32
B46: Terminal Value (Exit Mult.) ($M) | H46: =H14*H45
B47: PV of TV (Exit Mult.) ($M) | H47: =H46*H33
...

Sheet Base_Case
B2: Base Case — DCF Valuation
B3: Scenario: Base | 5-yr CAGR: 25% | WACC: 10.8% | Sustained AI demand, broad enterprise adoption, stable competitive moat
C4: FY2024A | D4: FY2025E | E4: FY2026E | F4: FY2027E | G4: FY2028E | H4: FY2029E | I4: FY2030E
B6: 1. Revenue Build
B7: Revenue ($M) | C7: =Assumptions!D8 | D7: =C7*(1+Assumptions!$D$9) | E7: =D7*(1+Assumptions!$D$9) | F7: =E7*(1+Assumptions!$D$9) | G7: =F7*(1+Assumptions!$D$9) | H7: =G7*(1+Assumptions!$D$9) | I7: =H7*(1+Assumptions!D10)
B8: YoY growth | C8: — | D8: =IFERROR(D7/C7-1,0) | E8: =IFERROR(E7/D7-1,0) | F8: =IFERROR(F7/E7-1,0) | G8: =IFERROR(G7/F7-1,0) | H8: =IFERROR(H7/G7-1,0) | I8: =IFERROR(I7/H7-1,0)
B10: 2. Income Statement
B11: Gross profit ($M) | C11: 44300 | D11: =D7*(Assumptions!$D$13+(Assumptions!$D$14-Assumptions!$D$13)*0.0) | E11: =E7*(Assumptions!$D$13+(Assumptions!$D$14-Assumptions!$D$13)*0.25) | F11: =F7*(Assumptions!$D$13+(Assumptions!$D$14-Assumptions!$D$13)*0.5) | G11: =G7*(Assumptions!$D$13+(Assumptions!$D$14-Assumptions!$D$13)*0.75) | H11: =H7*(Assumptions!$D$13+(Assumptions!$D$14-Assumptions!$D$13)*1.0) | I11: =I7*Assumptions!$D$14
B12: Gross margin % | C12: =IFERROR(C11/C7,0) | D12: =IFERROR(D11/D7,0) | E12: =IFERROR(E11/E7,0) | F12: =IFERROR(F11/F7,0) | G12: =IFERROR(G11/G7,0) | H12: =IFERROR(H11/H7,0) | I12: =IFERROR(I11/I7,0)
B13: Operating expenses ($M) | C13: 11600 | D13: =D7*(Assumptions!$D$15+(Assumptions!$D$16-Assumptions!$D$15)*0.0) | E13: =E7*(Assumptions!$D$15+(Assumptions!$D$16-Assumptions!$D$15)*0.25) | F13: =F7*(Assumptions!$D$15+(Assumptions!$D$16-Assumptions!$D$15)*0.5) | G13: =G7*(Assumptions!$D$15+(Assumptions!$D$16-Assumptions!$D$15)*0.75) | H13: =H7*(Assumptions!$D$15+(Assumptions!$D$16-Assumptions!$D$15)*1.0) | I13: =I7*Assumptions!$D$16
B14: EBITDA ($M) | C14: =C11-C13 | D14: =D11-D13 | E14: =E11-E13 | F14: =F11-F13 | G14: =G11-G13 | H14: =H11-H13 | I14: =I11-I13
B15: EBITDA margin % | C15: =IFERROR(C14/C7,0) | D15: =IFERROR(D14/D7,0) | E15: =IFERROR(E14/E7,0) | F15: =IFERROR(F14/F7,0) | G15: =IFERROR(G14/G7,0) | H15: =IFERROR(H14/H7,0) | I15: =IFERROR(I14/I7,0)
B16: Depreciation & amortization ($M) | C16: 2800 | D16: =D7*0.045 | E16: =E7*0.045 | F16: =F7*0.045 | G16: =G7*0.045 | H16: =H7*0.045 | I16: =I7*0.045
B17: EBIT ($M) | C17: =C14-C16 | D17: =D14-D16 | E17: =E14-E16 | F17: =F14-F16 | G17: =G14-G16 | H17: =H14-H16 | I17: =I14-I16
B18: EBIT margin % | C18: =IFERROR(C17/C7,0) | D18: =IFERROR(D17/D7,0) | E18: =IFERROR(E17/E7,0) | F18: =IFERROR(F17/F7,0) | G18: =IFERROR(G17/G7,0) | H18: =IFERROR(H17/H7,0) | I18: =IFERROR(I17/I7,0)
B19: Taxes ($M) | C19: 6300 | D19: =MAX(0,D17)*Assumptions!$D$19 | E19: =MAX(0,E17)*Assumptions!$D$19 | F19: =MAX(0,F17)*Assumptions!$D$19 | G19: =MAX(0,G17)*Assumptions!$D$19 | H19: =MAX(0,H17)*Assumptions!$D$19 | I19: =MAX(0,I17)*Assumptions!$D$19
B20: NOPAT ($M) | C20: =C17-C19 | D20: =D17-D19 | E20: =E17-E19 | F20: =F17-F19 | G20: =G17-G19 | H20: =H17-H19 | I20: =I17-I19
B22: 3. Unlevered Free Cash Flow Build
B23: NOPAT ($M) | C23: =C20 | D23: =D20 | E23: =E20 | F23: =F20 | G23: =G20 | H23: =H20 | I23: =I20
B24: (+) D&A | C24: =C16 | D24: =D16 | E24: =E16 | F24: =F16 | G24: =G16 | H24: =H16 | I24: =I16
B25: (–) Capital expenditures | C25: 3200 | D25: =D7*Assumptions!$D$17 | E25: =E7*Assumptions!$D$17 | F25: =F7*Assumptions!$D$17 | G25: =G7*Assumptions!$D$17 | H25: =H7*Assumptions!$D$17 | I25: =I7*Assumptions!$D$17
B26: (–) Δ Net working capital | C26: 0 | D26: =(D7-C7)*Assumptions!$D$18 | E26: =(E7-D7)*Assumptions!$D$18 | F26: =(F7-E7)*Assumptions!$D$18 | G26: =(G7-F7)*Assumptions!$D$18 | H26: =(H7-G7)*Assumptions!$D$18 | I26: =(I7-H7)*Assumptions!$D$18
B27: Unlevered Free Cash Flow ($M) | C27: =C23+C24-C25-C26 | D27: =D23+D24-D25-D26 | E27: =E23+E24-E25-E26 | F27: =F23+F24-F25-F26 | G27: =G23+G24-G25-G26 | H27: =H23+H24-H25-H26 | I27: =I23+I24-I25-I26
B28: FCF margin % | C28: =IFERROR(C27/C7,0) | D28: =IFERROR(D27/D7,0) | E28: =IFERROR(E27/E7,0) | F28: =IFERROR(F27/F7,0) | G28: =IFERROR(G27/G7,0) | H28: =IFERROR(H27/H7,0) | I28: =IFERROR(I27/I7,0)
B30: 4. WACC & Discounting
B31: WACC | C31: — | D31: =Assumptions!$D$28 | E31: =Assumptions!$D$28 | F31: =Assumptions!$D$28 | G31: =Assumptions!$D$28 | H31: =Assumptions!$D$28 | I31: =Assumptions!$D$28
B32: Discount period (yrs, mid-year) | C32: — | D32: =1-0.5 | E32: =2-0.5 | F32: =3-0.5 | G32: =4-0.5 | H32: =5-0.5 | I32: —
B33: Discount factor | D33: =1/(1+D31)^D32 | E33: =1/(1+E31)^E32 | F33: =1/(1+F31)^F32 | G33: =1/(1+G31)^G32 | H33: =1/(1+H31)^H32
B34: PV of unlevered FCF ($M) | D34: =D27*D33 | E34: =E27*E33 | F34: =F27*F33 | G34: =G27*G33 | H34: =H27*H33
B35: Sum PV of explicit FCF ($M) | C35: =SUM(D34:H34)
B37: 5. Terminal Value
B38: Terminal Year EBITDA ($M) | C38: — | H38: =H14
B39: Terminal year FCF ($M) | C39: — | H39: =H27
B40: Terminal growth rate (g) | C40: — | H40: =Assumptions!D10
B41: WACC – g | C41: — | H41: =H31-H40
B42: Terminal Value (Gordon) ($M) | H42: =H27*(1+H40)/(H31-H40)
B43: PV of Terminal Value ($M) | H43: =H42*H33
B45: Exit EV/EBITDA multiple (x) | C45: — | H45: =Assumptions!D32
B46: Terminal Value (Exit Mult.) ($M) | H46: =H14*H45
B47: PV of TV (Exit Mult.) ($M) | H47: =H46*H33
...

Sheet Bull_Case
B2: Bull Case — DCF Valuation
B3: Scenario: Bull | 5-yr CAGR: 40% | WACC: 10.0% | AI supercycle, AGI inflection, monopoly-like pricing power
C4: FY2024A | D4: FY2025E | E4: FY2026E | F4: FY2027E | G4: FY2028E | H4: FY2029E | I4: FY2030E
B6: 1. Revenue Build
B7: Revenue ($M) | C7: =Assumptions!E8 | D7: =C7*(1+Assumptions!$E$9) | E7: =D7*(1+Assumptions!$E$9) | F7: =E7*(1+Assumptions!$E$9) | G7: =F7*(1+Assumptions!$E$9) | H7: =G7*(1+Assumptions!$E$9) | I7: =H7*(1+Assumptions!E10)
B8: YoY growth | C8: — | D8: =IFERROR(D7/C7-1,0) | E8: =IFERROR(E7/D7-1,0) | F8: =IFERROR(F7/E7-1,0) | G8: =IFERROR(G7/F7-1,0) | H8: =IFERROR(H7/G7-1,0) | I8: =IFERROR(I7/H7-1,0)
B10: 2. Income Statement
B11: Gross profit ($M) | C11: 44300 | D11: =D7*(Assumptions!$E$13+(Assumptions!$E$14-Assumptions!$E$13)*0.0) | E11: =E7*(Assumptions!$E$13+(Assumptions!$E$14-Assumptions!$E$13)*0.25) | F11: =F7*(Assumptions!$E$13+(Assumptions!$E$14-Assumptions!$E$13)*0.5) | G11: =G7*(Assumptions!$E$13+(Assumptions!$E$14-Assumptions!$E$13)*0.75) | H11: =H7*(Assumptions!$E$13+(Assumptions!$E$14-Assumptions!$E$13)*1.0) | I11: =I7*Assumptions!$E$14
B12: Gross margin % | C12: =IFERROR(C11/C7,0) | D12: =IFERROR(D11/D7,0) | E12: =IFERROR(E11/E7,0) | F12: =IFERROR(F11/F7,0) | G12: =IFERROR(G11/G7,0) | H12: =IFERROR(H11/H7,0) | I12: =IFERROR(I11/I7,0)
B13: Operating expenses ($M) | C13: 11600 | D13: =D7*(Assumptions!$E$15+(Assumptions!$E$16-Assumptions!$E$15)*0.0) | E13: =E7*(Assumptions!$E$15+(Assumptions!$E$16-Assumptions!$E$15)*0.25) | F13: =F7*(Assumptions!$E$15+(Assumptions!$E$16-Assumptions!$E$15)*0.5) | G13: =G7*(Assumptions!$E$15+(Assumptions!$E$16-Assumptions!$E$15)*0.75) | H13: =H7*(Assumptions!$E$15+(Assumptions!$E$16-Assumptions!$E$15)*1.0) | I13: =I7*Assumptions!$E$16
B14: EBITDA ($M) | C14: =C11-C13 | D14: =D11-D13 | E14: =E11-E13 | F14: =F11-F13 | G14: =G11-G13 | H14: =H11-H13 | I14: =I11-I13
B15: EBITDA margin % | C15: =IFERROR(C14/C7,0) | D15: =IFERROR(D14/D7,0) | E15: =IFERROR(E14/E7,0) | F15: =IFERROR(F14/F7,0) | G15: =IFERROR(G14/G7,0) | H15: =IFERROR(H14/H7,0) | I15: =IFERROR(I14/I7,0)
B16: Depreciation & amortization ($M) | C16: 2800 | D16: =D7*0.045 | E16: =E7*0.045 | F16: =F7*0.045 | G16: =G7*0.045 | H16: =H7*0.045 | I16: =I7*0.045
B17: EBIT ($M) | C17: =C14-C16 | D17: =D14-D16 | E17: =E14-E16 | F17: =F14-F16 | G17: =G14-G16 | H17: =H14-H16 | I17: =I14-I16
B18: EBIT margin % | C18: =IFERROR(C17/C7,0) | D18: =IFERROR(D17/D7,0) | E18: =IFERROR(E17/E7,0) | F18: =IFERROR(F17/F7,0) | G18: =IFERROR(G17/G7,0) | H18: =IFERROR(H17/H7,0) | I18: =IFERROR(I17/I7,0)
B19: Taxes ($M) | C19: 6300 | D19: =MAX(0,D17)*Assumptions!$E$19 | E19: =MAX(0,E17)*Assumptions!$E$19 | F19: =MAX(0,F17)*Assumptions!$E$19 | G19: =MAX(0,G17)*Assumptions!$E$19 | H19: =MAX(0,H17)*Assumptions!$E$19 | I19: =MAX(0,I17)*Assumptions!$E$19
B20: NOPAT ($M) | C20: =C17-C19 | D20: =D17-D19 | E20: =E17-E19 | F20: =F17-F19 | G20: =G17-G19 | H20: =H17-H19 | I20: =I17-I19
B22: 3. Unlevered Free Cash Flow Build
B23: NOPAT ($M) | C23: =C20 | D23: =D20 | E23: =E20 | F23: =F20 | G23: =G20 | H23: =H20 | I23: =I20
B24: (+) D&A | C24: =C16 | D24: =D16 | E24: =E16 | F24: =F16 | G24: =G16 | H24: =H16 | I24: =I16
B25: (–) Capital expenditures | C25: 3200 | D25: =D7*Assumptions!$E$17 | E25: =E7*Assumptions!$E$17 | F25: =F7*Assumptions!$E$17 | G25: =G7*Assumptions!$E$17 | H25: =H7*Assumptions!$E$17 | I25: =I7*Assumptions!$E$17
B26: (–) Δ Net working capital | C26: 0 | D26: =(D7-C7)*Assumptions!$E$18 | E26: =(E7-D7)*Assumptions!$E$18 | F26: =(F7-E7)*Assumptions!$E$18 | G26: =(G7-F7)*Assumptions!$E$18 | H26: =(H7-G7)*Assumptions!$E$18 | I26: =(I7-H7)*Assumptions!$E$18
B27: Unlevered Free Cash Flow ($M) | C27: =C23+C24-C25-C26 | D27: =D23+D24-D25-D26 | E27: =E23+E24-E25-E26 | F27: =F23+F24-F25-F26 | G27: =G23+G24-G25-G26 | H27: =H23+H24-H25-H26 | I27: =I23+I24-I25-I26
B28: FCF margin % | C28: =IFERROR(C27/C7,0) | D28: =IFERROR(D27/D7,0) | E28: =IFERROR(E27/E7,0) | F28: =IFERROR(F27/F7,0) | G28: =IFERROR(G27/G7,0) | H28: =IFERROR(H27/H7,0) | I28: =IFERROR(I27/I7,0)
B30: 4. WACC & Discounting
B31: WACC | C31: — | D31: =Assumptions!$E$28 | E31: =Assumptions!$E$28 | F31: =Assumptions!$E$28 | G31: =Assumptions!$E$28 | H31: =Assumptions!$E$28 | I31: =Assumptions!$E$28
B32: Discount period (yrs, mid-year) | C32: — | D32: =1-0.5 | E32: =2-0.5 | F32: =3-0.5 | G32: =4-0.5 | H32: =5-0.5 | I32: —
B33: Discount factor | D33: =1/(1+D31)^D32 | E33: =1/(1+E31)^E32 | F33: =1/(1+F31)^F32 | G33: =1/(1+G31)^G32 | H33: =1/(1+H31)^H32
B34: PV of unlevered FCF ($M) | D34: =D27*D33 | E34: =E27*E33 | F34: =F27*F33 | G34: =G27*G33 | H34: =H27*H33
B35: Sum PV of explicit FCF ($M) | C35: =SUM(D34:H34)
B37: 5. Terminal Value
B38: Terminal Year EBITDA ($M) | C38: — | H38: =H14
B39: Terminal year FCF ($M) | C39: — | H39: =H27
B40: Terminal growth rate (g) | C40: — | H40: =Assumptions!E10
B41: WACC – g | C41: — | H41: =H31-H40
B42: Terminal Value (Gordon) ($M) | H42: =H27*(1+H40)/(H31-H40)
B43: PV of Terminal Value ($M) | H43: =H42*H33
B45: Exit EV/EBITDA multiple (x) | C45: — | H45: =Assumptions!E32
B46: Terminal Value (Exit Mult.) ($M) | H46: =H14*H45
B47: PV of TV (Exit Mult.) ($M) | H47: =H46*H33
...

Sheet Scenario_Summary
B2: Scenario Summary — Bear / Base / Bull
B4: Metric | C4: Bear | D4: Base | E4: Bull | F4: Unit
B5: 5-year revenue CAGR | C5: =Assumptions!C9 | D5: =Assumptions!D9 | E5: =Assumptions!E9
B6: Terminal growth rate (g) | C6: =Assumptions!C10 | D6: =Assumptions!D10 | E6: =Assumptions!E10
B7: WACC | C7: =Assumptions!C28 | D7: =Assumptions!D28 | E7: =Assumptions!E28
B8: Exit EV/EBITDA multiple | C8: =Assumptions!C32 | D8: =Assumptions!D32 | E8: =Assumptions!E32
B10: Valuation Outputs
B11: Sum PV of explicit FCF ($M) | C11: ='Bear_Case'!C35 | D11: ='Base_Case'!C35 | E11: ='Bull_Case'!C35
B12: PV of Terminal Value ($M) | C12: ='Bear_Case'!H43 | D12: ='Base_Case'!H43 | E12: ='Bull_Case'!H43
B13: Enterprise Value ($M) | C13: ='Bear_Case'!C52 | D13: ='Base_Case'!C52 | E13: ='Bull_Case'!C52
B14: Equity Value ($M) | C14: ='Bear_Case'!C55 | D14: ='Base_Case'!C55 | E14: ='Bull_Case'!C55
B15: Implied share price ($) | C15: ='Bear_Case'!C57 | D15: ='Base_Case'!C57 | E15: ='Bull_Case'!C57
B16: Upside / (Downside) % | C16: ='Bear_Case'!C59 | D16: ='Base_Case'!C59 | E16: ='Bull_Case'!C59
B18: Probability-Weighted Valuation
B19: Scenario probability | C19: 0.25 | D19: 0.5 | E19: 0.25 | F19: %
B20: Probability-weighted EV ($M) | C20: ='Bear_Case'!C52*C19 | D20: ='Base_Case'!C52*D19 | E20: ='Bull_Case'!C52*E19 | F20: Blended: | G20: =SUMPRODUCT(C20:E20,C19:E19)
B21: Probability-weighted Equity Value ($M) | C21: ='Bear_Case'!C55*C19 | D21: ='Base_Case'!C55*D19 | E21: ='Bull_Case'!C55*E19
B22: Probability-weighted share price ($) | C22: ='Bear_Case'!C57*C19 | D22: ='Base_Case'!C57*D19 | E22: ='Bull_Case'!C57*E19
B23: Blended upside / (downside) % | C23: =SUM(C22:E22)/Assumptions!D38-1
B25: Note: Probability weights are illustrative (25/50/25). Adjust the input cells to reflect your own scenario conviction. All scenario outputs flow from the Assumptions sheet — change any blue input there to update the entire model.

Sheet WACC_Sensitivity
B2: WACC Sensitivity — Implied Share Price ($)
B4: Two-way sensitivity table: rows = WACC, columns = Terminal Growth Rate (g). Cell values = implied share price ($) under Base case assumptions. Base case WACC and g highlighted in yellow.
B6: Implied Share Price ($) — Base Case
B7: WACC \ g | C7: 0.015 | D7: 0.02 | E7: 0.025 | F7: 0.03 | G7: 0.035 | H7: 0.04 | I7: 0.045 | J7: 0.05 | K7: 0.055
B8: 0.08 | C8: =IFERROR((((Base_Case!D27/(1+$B8)^0.5+Base_Case!E27/(1+$B8)^1.5+Base_Case!F27/(1+$B8)^2.5+Base_Case!G27/(1+$B8)^3.5+Base_Case!H27/(1+$B8)^4.5)+Base_Case!H27*(1+C$7)/($B8-C$7)/(1+$B8)^4.5)-Assumptions!D35+Assumptions!D36)/Assumptions!D37,0) | D8: =IFERROR((((Base_Case!D27/(1+$B8)^0.5+Base_Case!E27/(1+$B8)^1.5+Base_Case!F27/(1+$B8)^2.5+Base_Case!G27/(1+$B8)^3.5+Base_Case!H27/(1+$B8)^4.5)+Base_Case!H27*(1+D$7)/($B8-D$7)/(1+$B8)^4.5)-Assumptions!D35+Assumptions!D36)/Assumptions!D37,0) | E8: =IFERROR((((Base_Case!D27/(1+$B8)^0.5+Base_Case!E27/(1+$B8)^1.5+Base_Case!F27/(1+$B8)^2.5+Base_Case!G27/(1+$B8)^3.5+Base_Case!H27/(1+$B8)^4.5)+Base_Case!H27*(1+E$7)/($B8-E$7)/(1+$B8)^4.5)-Assumptions!D35+Assumptions!D36)/Assumptions!D37,0) | F8: =IFERROR((((Base_Case!D27/(1+$B8)^0.5+Base_Case!E27/(1+$B8)^1.5+Base_Case!F27/(1+$B8)^2.5+Base_Case!G27/(1+$B8)^3.5+Base_Case!H27/(1+$B8)^4.5)+Base_Case!H27*(1+F$7)/($B8-F$7)/(1+$B8)^4.5)-Assumptions!D35+Assumptions!D36)/Assumptions!D37,0) | G8: =IFERROR((((Base_Case!D27/(1+$B8)^0.5+Base_Case!E27/(1+$B8)^1.5+Base_Case!F27/(1+$B8)^2.5+Base_Case!G27/(1+$B8)^3.5+Base_Case!H27/(1+$B8)^4.5)+Base_Case!H27*(1+G$7)/($B8-G$7)/(1+$B8)^4.5)-Assumptions!D35+Assumptions!D36)/Assumptions!D37,0) | H8: =IFERROR((((Base_Case!D27/(1+$B8)^0.5+Base_Case!E27/(1+$B8)^1.5+Base_Case!F27/(1+$B8)^2.5+Base_Case!G27/(1+$B8)^3.5+Base_Case!H27/(1+$B8)^4.5)+Base_Case!H27*(1+H$7)/($B8-H$7)/(1+$B8)^4.5)-Assumptions!D35+Assumptions!D36)/Assumptions!D37,0) | I8: =IFERROR((((Base_Case!D27/(1+$B8)^0.5+Base_Case!E27/(1+$B8)^1.5+Base_Case!F27/(1+$B8)^2.5+Base_Case!G27/(1+$B8)^3.5+Base_Case!H27/(1+$B8)^4.5)+Base_Case!H27*(1+I$7)/($B8-I$7)/(1+$B8)^4.5)-Assumptions!D35+Assumptions!D36)/Assumptions!D37,0) | J8: =IFERROR((((Base_Case!D27/(1+$B8)^0.5+Base_Case!E27/(1+$B8)^1.5+Base_Case!F27/(1+$B8)^2.5+Base_Case!G27/(1+$B8)^3.5+Base_Case!H27/(1+$B8)^4.5)+Base_Case!H27*(1+J$7)/($B8-J$7)/(1+$B8)^4.5)-Assumptions!D35+Assumptions!D36)/Assumptions!D37,0) | K8: =IFERROR((((Base_Case!D27/(1+$B8)^0.5+Base_Case!E27/(1+$B8)^1.5+Base_Case!F27/(1+$B8)^2.5+Base_Case!G27/(1+$B8)^3.5+Base_Case!H27/(1+$B8)^4.5)+Base_Case!H27*(1+K$7)/($B8-K$7)/(1+$B8)^4.5)-Assumptions!D35+Assumptions!D36)/Assumptions!D37,0)
B9: 0.09 | C9: =IFERROR((((Base_Case!D27/(1+$B9)^0.5+Base_Case!E27/(1+$B9)^1.5+Base_Case!F27/(1+$B9)^2.5+Base_Case!G27/(1+$B9)^3.5+Base_Case!H27/(1+$B9)^4.5)+Base_Case!H27*(1+C$7)/($B9-C$7)/(1+$B9)^4.5)-Assumptions!D35+Assumptions!D36)/Assumptions!D37,0) | D9: =IFERROR((((Base_Case!D27/(1+$B9)^0.5+Base_Case!E27/(1+$B9)^1.5+Base_Case!F27/(1+$B9)^2.5+Base_Case!G27/(1+$B9)^3.5+Base_Case!H27/(1+$B9)^4.5)+Base_Case!H27*(1+D$7)/($B9-D$7)/(1+$B9)^4.5)-Assumptions!D35+Assumptions!D36)/Assumptions!D37,0) | E9: =IFERROR((((Base_Case!D27/(1+$B9)^0.5+Base_Case!E27/(1+$B9)^1.5+Base_Case!F27/(1+$B9)^2.5+Base_Case!G27/(1+$B9)^3.5+Base_Case!H27/(1+$B9)^4.5)+Base_Case!H27*(1+E$7)/($B9-E$7)/(1+$B9)^4.5)-Assumptions!D35+Assumptions!D36)/Assumptions!D37,0) | F9: =IFERROR((((Base_Case!D27/(1+$B9)^0.5+Base_Case!E27/(1+$B9)^1.5+Base_Case!F27/(1+$B9)^2.5+Base_Case!G27/(1+$B9)^3.5+Base_Case!H27/(1+$B9)^4.5)+Base_Case!H27*(1+F$7)/($B9-F$7)/(1+$B9)^4.5)-Assumptions!D35+Assumptions!D36)/Assumptions!D37,0) | G9: =IFERROR((((Base_Case!D27/(1+$B9)^0.5+Base_Case!E27/(1+$B9)^1.5+Base_Case!F27/(1+$B9)^2.5+Base_Case!G27/(1+$B9)^3.5+Base_Case!H27/(1+$B9)^4.5)+Base_Case!H27*(1+G$7)/($B9-G$7)/(1+$B9)^4.5)-Assumptions!D35+Assumptions!D36)/Assumptions!D37,0) | H9: =IFERROR((((Base_Case!D27/(1+$B9)^0.5+Base_Case!E27/(1+$B9)^1.5+Base_Case!F27/(1+$B9)^2.5+Base_Case!G27/(1+$B9)^3.5+Base_Case!H27/(1+$B9)^4.5)+Base_Case!H27*(1+H$7)/($B9-H$7)/(1+$B9)^4.5)-Assumptions!D35+Assumptions!D36)/Assumptions!D37,0) | I9: =IFERROR((((Base_Case!D27/(1+$B9)^0.5+Base_Case!E27/(1+$B9)^1.5+Base_Case!F27/(1+$B9)^2.5+Base_Case!G27/(1+$B9)^3.5+Base_Case!H27/(1+$B9)^4.5)+Base_Case!H27*(1+I$7)/($B9-I$7)/(1+$B9)^4.5)-Assumptions!D35+Assumptions!D36)/Assumptions!D37,0) | J9: =IFERROR((((Base_Case!D27/(1+$B9)^0.5+Base_Case!E27/(1+$B9)^1.5+Base_Case!F27/(1+$B9)^2.5+Base_Case!G27/(1+$B9)^3.5+Base_Case!H27/(1+$B9)^4.5)+Base_Case!H27*(1+J$7)/($B9-J$7)/(1+$B9)^4.5)-Assumptions!D35+Assumptions!D36)/Assumptions!D37,0) | K9: =IFERROR((((Base_Case!D27/(1+$B9)^0.5+Base_Case!E27/(1+$B9)^1.5+Base_Case!F27/(1+$B9)^2.5+Base_Case!G27/(1+$B9)^3.5+Base_Case!H27/(1+$B9)^4.5)+Base_Case!H27*(1+K$7)/($B9-K$7)/(1+$B9)^4.5)-Assumptions!D35+Assumptions!D36)/Assumptions!D37,0)
B10: 0.1 | C10: =IFERROR((((Base_Case!D27/(1+$B10)^0.5+Base_Case!E27/(1+$B10)^1.5+Base_Case!F27/(1+$B10)^2.5+Base_Case!G27/(1+$B10)^3.5+Base_Case!H27/(1+$B10)^4.5)+Base_Case!H27*(1+C$7)/($B10-C$7)/(1+$B10)^4.5)-Assumptions!D35+Assumptions!D36)/Assumptions!D37,0) | D10: =IFERROR((((Base_Case!D27/(1+$B10)^0.5+Base_Case!E27/(1+$B10)^1.5+Base_Case!F27/(1+$B10)^2.5+Base_Case!G27/(1+$B10)^3.5+Base_Case!H27/(1+$B10)^4.5)+Base_Case!H27*(1+D$7)/($B10-D$7)/(1+$B10)^4.5)-Assumptions!D35+Assumptions!D36)/Assumptions!D37,0) | E10: =IFERROR((((Base_Case!D27/(1+$B10)^0.5+Base_Case!E27/(1+$B10)^1.5+Base_Case!F27/(1+$B10)^2.5+Base_Case!G27/(1+$B10)^3.5+Base_Case!H27/(1+$B10)^4.5)+Base_Case!H27*(1+E$7)/($B10-E$7)/(1+$B10)^4.5)-Assumptions!D35+Assumptions!D36)/Assumptions!D37,0) | F10: =IFERROR((((Base_Case!D27/(1+$B10)^0.5+Base_Case!E27/(1+$B10)^1.5+Base_Case!F27/(1+$B10)^2.5+Base_Case!G27/(1+$B10)^3.5+Base_Case!H27/(1+$B10)^4.5)+Base_Case!H27*(1+F$7)/($B10-F$7)/(1+$B10)^4.5)-Assumptions!D35+Assumptions!D36)/Assumptions!D37,0) | G10: =IFERROR((((Base_Case!D27/(1+$B10)^0.5+Base_Case!E27/(1+$B10)^1.5+Base_Case!F27/(1+$B10)^2.5+Base_Case!G27/(1+$B10)^3.5+Base_Case!H27/(1+$B10)^4.5)+Base_Case!H27*(1+G$7)/($B10-G$7)/(1+$B10)^4.5)-Assumptions!D35+Assumptions!D36)/Assumptions!D37,0) | H10: =IFERROR((((Base_Case!D27/(1+$B10)^0.5+Base_Case!E27/(1+$B10)^1.5+Base_Case!F27/(1+$B10)^2.5+Base_Case!G27/(1+$B10)^3.5+Base_Case!H27/(1+$B10)^4.5)+Base_Case!H27*(1+H$7)/($B10-H$7)/(1+$B10)^4.5)-Assumptions!D35+Assumptions!D36)/Assumptions!D37,0) | I10: =IFERROR((((Base_Case!D27/(1+$B10)^0.5+Base_Case!E27/(1+$B10)^1.5+Base_Case!F27/(1+$B10)^2.5+Base_Case!G27/(1+$B10)^3.5+Base_Case!H27/(1+$B10)^4.5)+Base_Case!H27*(1+I$7)/($B10-I$7)/(1+$B10)^4.5)-Assumptions!D35+Assumptions!D36)/Assumptions!D37,0) | J10: =IFERROR((((Base_Case!D27/(1+$B10)^0.5+Base_Case!E27/(1+$B10)^1.5+Base_Case!F27/(1+$B10)^2.5+Base_Case!G27/(1+$B10)^3.5+Base_Case!H27/(1+$B10)^4.5)+Base_Case!H27*(1+J$7)/($B10-J$7)/(1+$B10)^4.5)-Assumptions!D35+Assumptions!D36)/Assumptions!D37,0) | K10: =IFERROR((((Base_Case!D27/(1+$B10)^0.5+Base_Case!E27/(1+$B10)^1.5+Base_Case!F27/(1+$B10)^2.5+Base_Case!G27/(1+$B10)^3.5+Base_Case!H27/(1+$B10)^4.5)+Base_Case!H27*(1+K$7)/($B10-K$7)/(1+$B10)^4.5)-Assumptions!D35+Assumptions!D36)/Assumptions!D37,0)
B11: 0.105 | C11: =IFERROR((((Base_Case!D27/(1+$B11)^0.5+Base_Case!E27/(1+$B11)^1.5+Base_Case!F27/(1+$B11)^2.5+Base_Case!G27/(1+$B11)^3.5+Base_Case!H27/(1+$B11)^4.5)+Base_Case!H27*(1+C$7)/($B11-C$7)/(1+$B11)^4.5)-Assumptions!D35+Assumptions!D36)/Assumptions!D37,0) | D11: =IFERROR((((Base_Case!D27/(1+$B11)^0.5+Base_Case!E27/(1+$B11)^1.5+Base_Case!F27/(1+$B11)^2.5+Base_Case!G27/(1+$B11)^3.5+Base_Case!H27/(1+$B11)^4.5)+Base_Case!H27*(1+D$7)/($B11-D$7)/(1+$B11)^4.5)-Assumptions!D35+Assumptions!D36)/Assumptions!D37,0) | E11: =IFERROR((((Base_Case!D27/(1+$B11)^0.5+Base_Case!E27/(1+$B11)^1.5+Base_Case!F27/(1+$B11)^2.5+Base_Case!G27/(1+$B11)^3.5+Base_Case!H27/(1+$B11)^4.5)+Base_Case!H27*(1+E$7)/($B11-E$7)/(1+$B11)^4.5)-Assumptions!D35+Assumptions!D36)/Assumptions!D37,0) | F11: =IFERROR((((Base_Case!D27/(1+$B11)^0.5+Base_Case!E27/(1+$B11)^1.5+Base_Case!F27/(1+$B11)^2.5+Base_Case!G27/(1+$B11)^3.5+Base_Case!H27/(1+$B11)^4.5)+Base_Case!H27*(1+F$7)/($B11-F$7)/(1+$B11)^4.5)-Assumptions!D35+Assumptions!D36)/Assumptions!D37,0) | G11: =IFERROR((((Base_Case!D27/(1+$B11)^0.5+Base_Case!E27/(1+$B11)^1.5+Base_Case!F27/(1+$B11)^2.5+Base_Case!G27/(1+$B11)^3.5+Base_Case!H27/(1+$B11)^4.5)+Base_Case!H27*(1+G$7)/($B11-G$7)/(1+$B11)^4.5)-Assumptions!D35+Assumptions!D36)/Assumptions!D37,0) | H11: =IFERROR((((Base_Case!D27/(1+$B11)^0.5+Base_Case!E27/(1+$B11)^1.5+Base_Case!F27/(1+$B11)^2.5+Base_Case!G27/(1+$B11)^3.5+Base_Case!H27/(1+$B11)^4.5)+Base_Case!H27*(1+H$7)/($B11-H$7)/(1+$B11)^4.5)-Assumptions!D35+Assumptions!D36)/Assumptions!D37,0) | I11: =IFERROR((((Base_Case!D27/(1+$B11)^0.5+Base_Case!E27/(1+$B11)^1.5+Base_Case!F27/(1+$B11)^2.5+Base_Case!G27/(1+$B11)^3.5+Base_Case!H27/(1+$B11)^4.5)+Base_Case!H27*(1+I$7)/($B11-I$7)/(1+$B11)^4.5)-Assumptions!D35+Assumptions!D36)/Assumptions!D37,0) | J11: =IFERROR((((Base_Case!D27/(1+$B11)^0.5+Base_Case!E27/(1+$B11)^1.5+Base_Case!F27/(1+$B11)^2.5+Base_Case!G27/(1+$B11)^3.5+Base_Case!H27/(1+$B11)^4.5)+Base_Case!H27*(1+J$7)/($B11-J$7)/(1+$B11)^4.5)-Assumptions!D35+Assumptions!D36)/Assumptions!D37,0) | K11: =IFERROR((((Base_Case!D27/(1+$B11)^0.5+Base_Case!E27/(1+$B11)^1.5+Base_Case!F27/(1+$B11)^2.5+Base_Case!G27/(1+$B11)^3.5+Base_Case!H27/(1+$B11)^4.5)+Base_Case!H27*(1+K$7)/($B11-K$7)/(1+$B11)^4.5)-Assumptions!D35+Assumptions!D36)/Assumptions!D37,0)
B12: 0.11 | C12: =IFERROR((((Base_Case!D27/(1+$B12)^0.5+Base_Case!E27/(1+$B12)^1.5+Base_Case!F27/(1+$B12)^2.5+Base_Case!G27/(1+$B12)^3.5+Base_Case!H27/(1+$B12)^4.5)+Base_Case!H27*(1+C$7)/($B12-C$7)/(1+$B12)^4.5)-Assumptions!D35+Assumptions!D36)/Assumptions!D37,0) | D12: =IFERROR((((Base_Case!D27/(1+$B12)^0.5+Base_Case!E27/(1+$B12)^1.5+Base_Case!F27/(1+$B12)^2.5+Base_Case!G27/(1+$B12)^3.5+Base_Case!H27/(1+$B12)^4.5)+Base_Case!H27*(1+D$7)/($B12-D$7)/(1+$B12)^4.5)-Assumptions!D35+Assumptions!D36)/Assumptions!D37,0) | E12: =IFERROR((((Base_Case!D27/(1+$B12)^0.5+Base_Case!E27/(1+$B12)^1.5+Base_Case!F27/(1+$B12)^2.5+Base_Case!G27/(1+$B12)^3.5+Base_Case!H27/(1+$B12)^4.5)+Base_Case!H27*(1+E$7)/($B12-E$7)/(1+$B12)^4.5)-Assumptions!D35+Assumptions!D36)/Assumptions!D37,0) | F12: =IFERROR((((Base_Case!D27/(1+$B12)^0.5+Base_Case!E27/(1+$B12)^1.5+Base_Case!F27/(1+$B12)^2.5+Base_Case!G27/(1+$B12)^3.5+Base_Case!H27/(1+$B12)^4.5)+Base_Case!H27*(1+F$7)/($B12-F$7)/(1+$B12)^4.5)-Assumptions!D35+Assumptions!D36)/Assumptions!D37,0) | G12: =IFERROR((((Base_Case!D27/(1+$B12)^0.5+Base_Case!E27/(1+$B12)^1.5+Base_Case!F27/(1+$B12)^2.5+Base_Case!G27/(1+$B12)^3.5+Base_Case!H27/(1+$B12)^4.5)+Base_Case!H27*(1+G$7)/($B12-G$7)/(1+$B12)^4.5)-Assumptions!D35+Assumptions!D36)/Assumptions!D37,0) | H12: =IFERROR((((Base_Case!D27/(1+$B12)^0.5+Base_Case!E27/(1+$B12)^1.5+Base_Case!F27/(1+$B12)^2.5+Base_Case!G27/(1+$B12)^3.5+Base_Case!H27/(1+$B12)^4.5)+Base_Case!H27*(1+H$7)/($B12-H$7)/(1+$B12)^4.5)-Assumptions!D35+Assumptions!D36)/Assumptions!D37,0) | I12: =IFERROR((((Base_Case!D27/(1+$B12)^0.5+Base_Case!E27/(1+$B12)^1.5+Base_Case!F27/(1+$B12)^2.5+Base_Case!G27/(1+$B12)^3.5+Base_Case!H27/(1+$B12)^4.5)+Base_Case!H27*(1+I$7)/($B12-I$7)/(1+$B12)^4.5)-Assumptions!D35+Assumptions!D36)/Assumptions!D37,0) | J12: =IFERROR((((Base_Case!D27/(1+$B12)^0.5+Base_Case!E27/(1+$B12)^1.5+Base_Case!F27/(1+$B12)^2.5+Base_Case!G27/(1+$B12)^3.5+Base_Case!H27/(1+$B12)^4.5)+Base_Case!H27*(1+J$7)/($B12-J$7)/(1+$B12)^4.5)-Assumptions!D35+Assumptions!D36)/Assumptions!D37,0) | K12: =IFERROR((((Base_Case!D27/(1+$B12)^0.5+Base_Case!E27/(1+$B12)^1.5+Base_Case!F27/(1+$B12)^2.5+Base_Case!G27/(1+$B12)^3.5+Base_Case!H27/(1+$B12)^4.5)+Base_Case!H27*(1+K$7)/($B12-K$7)/(1+$B12)^4.5)-Assumptions!D35+Assumptions!D36)/Assumptions!D37,0)
B13: 0.115 | C13: =IFERROR((((Base_Case!D27/(1+$B13)^0.5+Base_Case!E27/(1+$B13)^1.5+Base_Case!F27/(1+$B13)^2.5+Base_Case!G27/(1+$B13)^3.5+Base_Case!H27/(1+$B13)^4.5)+Base_Case!H27*(1+C$7)/($B13-C$7)/(1+$B13)^4.5)-Assumptions!D35+Assumptions!D36)/Assumptions!D37,0) | D13: =IFERROR((((Base_Case!D27/(1+$B13)^0.5+Base_Case!E27/(1+$B13)^1.5+Base_Case!F27/(1+$B13)^2.5+Base_Case!G27/(1+$B13)^3.5+Base_Case!H27/(1+$B13)^4.5)+Base_Case!H27*(1+D$7)/($B13-D$7)/(1+$B13)^4.5)-Assumptions!D35+Assumptions!D36)/Assumptions!D37,0) | E13: =IFERROR((((Base_Case!D27/(1+$B13)^0.5+Base_Case!E27/(1+$B13)^1.5+Base_Case!F27/(1+$B13)^2.5+Base_Case!G27/(1+$B13)^3.5+Base_Case!H27/(1+$B13)^4.5)+Base_Case!H27*(1+E$7)/($B13-E$7)/(1+$B13)^4.5)-Assumptions!D35+Assumptions!D36)/Assumptions!D37,0) | F13: =IFERROR((((Base_Case!D27/(1+$B13)^0.5+Base_Case!E27/(1+$B13)^1.5+Base_Case!F27/(1+$B13)^2.5+Base_Case!G27/(1+$B13)^3.5+Base_Case!H27/(1+$B13)^4.5)+Base_Case!H27*(1+F$7)/($B13-F$7)/(1+$B13)^4.5)-Assumptions!D35+Assumptions!D36)/Assumptions!D37,0) | G13: =IFERROR((((Base_Case!D27/(1+$B13)^0.5+Base_Case!E27/(1+$B13)^1.5+Base_Case!F27/(1+$B13)^2.5+Base_Case!G27/(1+$B13)^3.5+Base_Case!H27/(1+$B13)^4.5)+Base_Case!H27*(1+G$7)/($B13-G$7)/(1+$B13)^4.5)-Assumptions!D35+Assumptions!D36)/Assumptions!D37,0) | H13: =IFERROR((((Base_Case!D27/(1+$B13)^0.5+Base_Case!E27/(1+$B13)^1.5+Base_Case!F27/(1+$B13)^2.5+Base_Case!G27/(1+$B13)^3.5+Base_Case!H27/(1+$B13)^4.5)+Base_Case!H27*(1+H$7)/($B13-H$7)/(1+$B13)^4.5)-Assumptions!D35+Assumptions!D36)/Assumptions!D37,0) | I13: =IFERROR((((Base_Case!D27/(1+$B13)^0.5+Base_Case!E27/(1+$B13)^1.5+Base_Case!F27/(1+$B13)^2.5+Base_Case!G27/(1+$B13)^3.5+Base_Case!H27/(1+$B13)^4.5)+Base_Case!H27*(1+I$7)/($B13-I$7)/(1+$B13)^4.5)-Assumptions!D35+Assumptions!D36)/Assumptions!D37,0) | J13: =IFERROR((((Base_Case!D27/(1+$B13)^0.5+Base_Case!E27/(1+$B13)^1.5+Base_Case!F27/(1+$B13)^2.5+Base_Case!G27/(1+$B13)^3.5+Base_Case!H27/(1+$B13)^4.5)+Base_Case!H27*(1+J$7)/($B13-J$7)/(1+$B13)^4.5)-Assumptions!D35+Assumptions!D36)/Assumptions!D37,0) | K13: =IFERROR((((Base_Case!D27/(1+$B13)^0.5+Base_Case!E27/(1+$B13)^1.5+Base_Case!F27/(1+$B13)^2.5+Base_Case!G27/(1+$B13)^3.5+Base_Case!H27/(1+$B13)^4.5)+Base_Case!H27*(1+K$7)/($B13-K$7)/(1+$B13)^4.5)-Assumptions!D35+Assumptions!D36)/Assumptions!D37,0)
B14: 0.12 | C14: =IFERROR((((Base_Case!D27/(1+$B14)^0.5+Base_Case!E27/(1+$B14)^1.5+Base_Case!F27/(1+$B14)^2.5+Base_Case!G27/(1+$B14)^3.5+Base_Case!H27/(1+$B14)^4.5)+Base_Case!H27*(1+C$7)/($B14-C$7)/(1+$B14)^4.5)-Assumptions!D35+Assumptions!D36)/Assumptions!D37,0) | D14: =IFERROR((((Base_Case!D27/(1+$B14)^0.5+Base_Case!E27/(1+$B14)^1.5+Base_Case!F27/(1+$B14)^2.5+Base_Case!G27/(1+$B14)^3.5+Base_Case!H27/(1+$B14)^4.5)+Base_Case!H27*(1+D$7)/($B14-D$7)/(1+$B14)^4.5)-Assumptions!D35+Assumptions!D36)/Assumptions!D37,0) | E14: =IFERROR((((Base_Case!D27/(1+$B14)^0.5+Base_Case!E27/(1+$B14)^1.5+Base_Case!F27/(1+$B14)^2.5+Base_Case!G27/(1+$B14)^3.5+Base_Case!H27/(1+$B14)^4.5)+Base_Case!H27*(1+E$7)/($B14-E$7)/(1+$B14)^4.5)-Assumptions!D35+Assumptions!D36)/Assumptions!D37,0) | F14: =IFERROR((((Base_Case!D27/(1+$B14)^0.5+Base_Case!E27/(1+$B14)^1.5+Base_Case!F27/(1+$B14)^2.5+Base_Case!G27/(1+$B14)^3.5+Base_Case!H27/(1+$B14)^4.5)+Base_Case!H27*(1+F$7)/($B14-F$7)/(1+$B14)^4.5)-Assumptions!D35+Assumptions!D36)/Assumptions!D37,0) | G14: =IFERROR((((Base_Case!D27/(1+$B14)^0.5+Base_Case!E27/(1+$B14)^1.5+Base_Case!F27/(1+$B14)^2.5+Base_Case!G27/(1+$B14)^3.5+Base_Case!H27/(1+$B14)^4.5)+Base_Case!H27*(1+G$7)/($B14-G$7)/(1+$B14)^4.5)-Assumptions!D35+Assumptions!D36)/Assumptions!D37,0) | H14: =IFERROR((((Base_Case!D27/(1+$B14)^0.5+Base_Case!E27/(1+$B14)^1.5+Base_Case!F27/(1+$B14)^2.5+Base_Case!G27/(1+$B14)^3.5+Base_Case!H27/(1+$B14)^4.5)+Base_Case!H27*(1+H$7)/($B14-H$7)/(1+$B14)^4.5)-Assumptions!D35+Assumptions!D36)/Assumptions!D37,0) | I14: =IFERROR((((Base_Case!D27/(1+$B14)^0.5+Base_Case!E27/(1+$B14)^1.5+Base_Case!F27/(1+$B14)^2.5+Base_Case!G27/(1+$B14)^3.5+Base_Case!H27/(1+$B14)^4.5)+Base_Case!H27*(1+I$7)/($B14-I$7)/(1+$B14)^4.5)-Assumptions!D35+Assumptions!D36)/Assumptions!D37,0) | J14: =IFERROR((((Base_Case!D27/(1+$B14)^0.5+Base_Case!E27/(1+$B14)^1.5+Base_Case!F27/(1+$B14)^2.5+Base_Case!G27/(1+$B14)^3.5+Base_Case!H27/(1+$B14)^4.5)+Base_Case!H27*(1+J$7)/($B14-J$7)/(1+$B14)^4.5)-Assumptions!D35+Assumptions!D36)/Assumptions!D37,0) | K14: =IFERROR((((Base_Case!D27/(1+$B14)^0.5+Base_Case!E27/(1+$B14)^1.5+Base_Case!F27/(1+$B14)^2.5+Base_Case!G27/(1+$B14)^3.5+Base_Case!H27/(1+$B14)^4.5)+Base_Case!H27*(1+K$7)/($B14-K$7)/(1+$B14)^4.5)-Assumptions!D35+Assumptions!D36)/Assumptions!D37,0)
B15: 0.13 | C15: =IFERROR((((Base_Case!D27/(1+$B15)^0.5+Base_Case!E27/(1+$B15)^1.5+Base_Case!F27/(1+$B15)^2.5+Base_Case!G27/(1+$B15)^3.5+Base_Case!H27/(1+$B15)^4.5)+Base_Case!H27*(1+C$7)/($B15-C$7)/(1+$B15)^4.5)-Assumptions!D35+Assumptions!D36)/Assumptions!D37,0) | D15: =IFERROR((((Base_Case!D27/(1+$B15)^0.5+Base_Case!E27/(1+$B15)^1.5+Base_Case!F27/(1+$B15)^2.5+Base_Case!G27/(1+$B15)^3.5+Base_Case!H27/(1+$B15)^4.5)+Base_Case!H27*(1+D$7)/($B15-D$7)/(1+$B15)^4.5)-Assumptions!D35+Assumptions!D36)/Assumptions!D37,0) | E15: =IFERROR((((Base_Case!D27/(1+$B15)^0.5+Base_Case!E27/(1+$B15)^1.5+Base_Case!F27/(1+$B15)^2.5+Base_Case!G27/(1+$B15)^3.5+Base_Case!H27/(1+$B15)^4.5)+Base_Case!H27*(1+E$7)/($B15-E$7)/(1+$B15)^4.5)-Assumptions!D35+Assumptions!D36)/Assumptions!D37,0) | F15: =IFERROR((((Base_Case!D27/(1+$B15)^0.5+Base_Case!E27/(1+$B15)^1.5+Base_Case!F27/(1+$B15)^2.5+Base_Case!G27/(1+$B15)^3.5+Base_Case!H27/(1+$B15)^4.5)+Base_Case!H27*(1+F$7)/($B15-F$7)/(1+$B15)^4.5)-Assumptions!D35+Assumptions!D36)/Assumptions!D37,0) | G15: =IFERROR((((Base_Case!D27/(1+$B15)^0.5+Base_Case!E27/(1+$B15)^1.5+Base_Case!F27/(1+$B15)^2.5+Base_Case!G27/(1+$B15)^3.5+Base_Case!H27/(1+$B15)^4.5)+Base_Case!H27*(1+G$7)/($B15-G$7)/(1+$B15)^4.5)-Assumptions!D35+Assumptions!D36)/Assumptions!D37,0) | H15: =IFERROR((((Base_Case!D27/(1+$B15)^0.5+Base_Case!E27/(1+$B15)^1.5+Base_Case!F27/(1+$B15)^2.5+Base_Case!G27/(1+$B15)^3.5+Base_Case!H27/(1+$B15)^4.5)+Base_Case!H27*(1+H$7)/($B15-H$7)/(1+$B15)^4.5)-Assumptions!D35+Assumptions!D36)/Assumptions!D37,0) | I15: =IFERROR((((Base_Case!D27/(1+$B15)^0.5+Base_Case!E27/(1+$B15)^1.5+Base_Case!F27/(1+$B15)^2.5+Base_Case!G27/(1+$B15)^3.5+Base_Case!H27/(1+$B15)^4.5)+Base_Case!H27*(1+I$7)/($B15-I$7)/(1+$B15)^4.5)-Assumptions!D35+Assumptions!D36)/Assumptions!D37,0) | J15: =IFERROR((((Base_Case!D27/(1+$B15)^0.5+Base_Case!E27/(1+$B15)^1.5+Base_Case!F27/(1+$B15)^2.5+Base_Case!G27/(1+$B15)^3.5+Base_Case!H27/(1+$B15)^4.5)+Base_Case!H27*(1+J$7)/($B15-J$7)/(1+$B15)^4.5)-Assumptions!D35+Assumptions!D36)/Assumptions!D37,0) | K15: =IFERROR((((Base_Case!D27/(1+$B15)^0.5+Base_Case!E27/(1+$B15)^1.5+Base_Case!F27/(1+$B15)^2.5+Base_Case!G27/(1+$B15)^3.5+Base_Case!H27/(1+$B15)^4.5)+Base_Case!H27*(1+K$7)/($B15-K$7)/(1+$B15)^4.5)-Assumptions!D35+Assumptions!D36)/Assumptions!D37,0)
B18: Current share price: | C18: =Assumptions!D38
B19: Base case WACC: | C19: =Assumptions!D28
B20: Base case terminal g: | C20: =Assumptions!D10
B22: Methodology: Each cell recomputes the full DCF using Base case unlevered FCFs (Base_Case row 27) but overrides WACC (row input) and terminal growth (column input). Mid-year discounting applied. Debt, cash, and shares held constant at Base case.

Sheet TV_Sensitivity
B2: Terminal Value Sensitivity — Implied Share Price ($)
B4: Two-way sensitivity table: rows = Exit EV/EBITDA multiple, columns = WACC. Cell values = implied share price ($) under Base case assumptions, using the Exit Multiple terminal value method. Base case highlighted in yellow.
B6: Implied Share Price ($) — Exit Multiple Method (Base Case)
B7: EV/EBITDA \ WACC | C7: 0.08 | D7: 0.09 | E7: 0.1 | F7: 0.105 | G7: 0.11 | H7: 0.115 | I7: 0.12 | J7: 0.13 | K7: 0.14
B8: 12 | C8: =IFERROR((((Base_Case!D27/(1+C$7)^0.5+Base_Case!E27/(1+C$7)^1.5+Base_Case!F27/(1+C$7)^2.5+Base_Case!G27/(1+C$7)^3.5+Base_Case!H27/(1+C$7)^4.5)+Base_Case!H14*$B8/(1+C$7)^4.5)-Assumptions!D35+Assumptions!D36)/Assumptions!D37,0) | D8: =IFERROR((((Base_Case!D27/(1+D$7)^0.5+Base_Case!E27/(1+D$7)^1.5+Base_Case!F27/(1+D$7)^2.5+Base_Case!G27/(1+D$7)^3.5+Base_Case!H27/(1+D$7)^4.5)+Base_Case!H14*$B8/(1+D$7)^4.5)-Assumptions!D35+Assumptions!D36)/Assumptions!D37,0) | E8: =IFERROR((((Base_Case!D27/(1+E$7)^0.5+Base_Case!E27/(1+E$7)^1.5+Base_Case!F27/(1+E$7)^2.5+Base_Case!G27/(1+E$7)^3.5+Base_Case!H27/(1+E$7)^4.5)+Base_Case!H14*$B8/(1+E$7)^4.5)-Assumptions!D35+Assumptions!D36)/Assumptions!D37,0) | F8: =IFERROR((((Base_Case!D27/(1+F$7)^0.5+Base_Case!E27/(1+F$7)^1.5+Base_Case!F27/(1+F$7)^2.5+Base_Case!G27/(1+F$7)^3.5+Base_Case!H27/(1+F$7)^4.5)+Base_Case!H14*$B8/(1+F$7)^4.5)-Assumptions!D35+Assumptions!D36)/Assumptions!D37,0) | G8: =IFERROR((((Base_Case!D27/(1+G$7)^0.5+Base_Case!E27/(1+G$7)^1.5+Base_Case!F27/(1+G$7)^2.5+Base_Case!G27/(1+G$7)^3.5+Base_Case!H27/(1+G$7)^4.5)+Base_Case!H14*$B8/(1+G$7)^4.5)-Assumptions!D35+Assumptions!D36)/Assumptions!D37,0) | H8: =IFERROR((((Base_Case!D27/(1+H$7)^0.5+Base_Case!E27/(1+H$7)^1.5+Base_Case!F27/(1+H$7)^2.5+Base_Case!G27/(1+H$7)^3.5+Base_Case!H27/(1+H$7)^4.5)+Base_Case!H14*$B8/(1+H$7)^4.5)-Assumptions!D35+Assumptions!D36)/Assumptions!D37,0) | I8: =IFERROR((((Base_Case!D27/(1+I$7)^0.5+Base_Case!E27/(1+I$7)^1.5+Base_Case!F27/(1+I$7)^2.5+Base_Case!G27/(1+I$7)^3.5+Base_Case!H27/(1+I$7)^4.5)+Base_Case!H14*$B8/(1+I$7)^4.5)-Assumptions!D35+Assumptions!D36)/Assumptions!D37,0) | J8: =IFERROR((((Base_Case!D27/(1+J$7)^0.5+Base_Case!E27/(1+J$7)^1.5+Base_Case!F27/(1+J$7)^2.5+Base_Case!G27/(1+J$7)^3.5+Base_Case!H27/(1+J$7)^4.5)+Base_Case!H14*$B8/(1+J$7)^4.5)-Assumptions!D35+Assumptions!D36)/Assumptions!D37,0) | K8: =IFERROR((((Base_Case!D27/(1+K$7)^0.5+Base_Case!E27/(1+K$7)^1.5+Base_Case!F27/(1+K$7)^2.5+Base_Case!G27/(1+K$7)^3.5+Base_Case!H27/(1+K$7)^4.5)+Base_Case!H14*$B8/(1+K$7)^4.5)-Assumptions!D35+Assumptions!D36)/Assumptions!D37,0)
B9: 14 | C9: =IFERROR((((Base_Case!D27/(1+C$7)^0.5+Base_Case!E27/(1+C$7)^1.5+Base_Case!F27/(1+C$7)^2.5+Base_Case!G27/(1+C$7)^3.5+Base_Case!H27/(1+C$7)^4.5)+Base_Case!H14*$B9/(1+C$7)^4.5)-Assumptions!D35+Assumptions!D36)/Assumptions!D37,0) | D9: =IFERROR((((Base_Case!D27/(1+D$7)^0.5+Base_Case!E27/(1+D$7)^1.5+Base_Case!F27/(1+D$7)^2.5+Base_Case!G27/(1+D$7)^3.5+Base_Case!H27/(1+D$7)^4.5)+Base_Case!H14*$B9/(1+D$7)^4.5)-Assumptions!D35+Assumptions!D36)/Assumptions!D37,0) | E9: =IFERROR((((Base_Case!D27/(1+E$7)^0.5+Base_Case!E27/(1+E$7)^1.5+Base_Case!F27/(1+E$7)^2.5+Base_Case!G27/(1+E$7)^3.5+Base_Case!H27/(1+E$7)^4.5)+Base_Case!H14*$B9/(1+E$7)^4.5)-Assumptions!D35+Assumptions!D36)/Assumptions!D37,0) | F9: =IFERROR((((Base_Case!D27/(1+F$7)^0.5+Base_Case!E27/(1+F$7)^1.5+Base_Case!F27/(1+F$7)^2.5+Base_Case!G27/(1+F$7)^3.5+Base_Case!H27/(1+F$7)^4.5)+Base_Case!H14*$B9/(1+F$7)^4.5)-Assumptions!D35+Assumptions!D36)/Assumptions!D37,0) | G9: =IFERROR((((Base_Case!D27/(1+G$7)^0.5+Base_Case!E27/(1+G$7)^1.5+Base_Case!F27/(1+G$7)^2.5+Base_Case!G27/(1+G$7)^3.5+Base_Case!H27/(1+G$7)^4.5)+Base_Case!H14*$B9/(1+G$7)^4.5)-Assumptions!D35+Assumptions!D36)/Assumptions!D37,0) | H9: =IFERROR((((Base_Case!D27/(1+H$7)^0.5+Base_Case!E27/(1+H$7)^1.5+Base_Case!F27/(1+H$7)^2.5+Base_Case!G27/(1+H$7)^3.5+Base_Case!H27/(1+H$7)^4.5)+Base_Case!H14*$B9/(1+H$7)^4.5)-Assumptions!D35+Assumptions!D36)/Assumptions!D37,0) | I9: =IFERROR((((Base_Case!D27/(1+I$7)^0.5+Base_Case!E27/(1+I$7)^1.5+Base_Case!F27/(1+I$7)^2.5+Base_Case!G27/(1+I$7)^3.5+Base_Case!H27/(1+I$7)^4.5)+Base_Case!H14*$B9/(1+I$7)^4.5)-Assumptions!D35+Assumptions!D36)/Assumptions!D37,0) | J9: =IFERROR((((Base_Case!D27/(1+J$7)^0.5+Base_Case!E27/(1+J$7)^1.5+Base_Case!F27/(1+J$7)^2.5+Base_Case!G27/(1+J$7)^3.5+Base_Case!H27/(1+J$7)^4.5)+Base_Case!H14*$B9/(1+J$7)^4.5)-Assumptions!D35+Assumptions!D36)/Assumptions!D37,0) | K9: =IFERROR((((Base_Case!D27/(1+K$7)^0.5+Base_Case!E27/(1+K$7)^1.5+Base_Case!F27/(1+K$7)^2.5+Base_Case!G27/(1+K$7)^3.5+Base_Case!H27/(1+K$7)^4.5)+Base_Case!H14*$B9/(1+K$7)^4.5)-Assumptions!D35+Assumptions!D36)/Assumptions!D37,0)
B10: 16 | C10: =IFERROR((((Base_Case!D27/(1+C$7)^0.5+Base_Case!E27/(1+C$7)^1.5+Base_Case!F27/(1+C$7)^2.5+Base_Case!G27/(1+C$7)^3.5+Base_Case!H27/(1+C$7)^4.5)+Base_Case!H14*$B10/(1+C$7)^4.5)-Assumptions!D35+Assumptions!D36)/Assumptions!D37,0) | D10: =IFERROR((((Base_Case!D27/(1+D$7)^0.5+Base_Case!E27/(1+D$7)^1.5+Base_Case!F27/(1+D$7)^2.5+Base_Case!G27/(1+D$7)^3.5+Base_Case!H27/(1+D$7)^4.5)+Base_Case!H14*$B10/(1+D$7)^4.5)-Assumptions!D35+Assumptions!D36)/Assumptions!D37,0) | E10: =IFERROR((((Base_Case!D27/(1+E$7)^0.5+Base_Case!E27/(1+E$7)^1.5+Base_Case!F27/(1+E$7)^2.5+Base_Case!G27/(1+E$7)^3.5+Base_Case!H27/(1+E$7)^4.5)+Base_Case!H14*$B10/(1+E$7)^4.5)-Assumptions!D35+Assumptions!D36)/Assumptions!D37,0) | F10: =IFERROR((((Base_Case!D27/(1+F$7)^0.5+Base_Case!E27/(1+F$7)^1.5+Base_Case!F27/(1+F$7)^2.5+Base_Case!G27/(1+F$7)^3.5+Base_Case!H27/(1+F$7)^4.5)+Base_Case!H14*$B10/(1+F$7)^4.5)-Assumptions!D35+Assumptions!D36)/Assumptions!D37,0) | G10: =IFERROR((((Base_Case!D27/(1+G$7)^0.5+Base_Case!E27/(1+G$7)^1.5+Base_Case!F27/(1+G$7)^2.5+Base_Case!G27/(1+G$7)^3.5+Base_Case!H27/(1+G$7)^4.5)+Base_Case!H14*$B10/(1+G$7)^4.5)-Assumptions!D35+Assumptions!D36)/Assumptions!D37,0) | H10: =IFERROR((((Base_Case!D27/(1+H$7)^0.5+Base_Case!E27/(1+H$7)^1.5+Base_Case!F27/(1+H$7)^2.5+Base_Case!G27/(1+H$7)^3.5+Base_Case!H27/(1+H$7)^4.5)+Base_Case!H14*$B10/(1+H$7)^4.5)-Assumptions!D35+Assumptions!D36)/Assumptions!D37,0) | I10: =IFERROR((((Base_Case!D27/(1+I$7)^0.5+Base_Case!E27/(1+I$7)^1.5+Base_Case!F27/(1+I$7)^2.5+Base_Case!G27/(1+I$7)^3.5+Base_Case!H27/(1+I$7)^4.5)+Base_Case!H14*$B10/(1+I$7)^4.5)-Assumptions!D35+Assumptions!D36)/Assumptions!D37,0) | J10: =IFERROR((((Base_Case!D27/(1+J$7)^0.5+Base_Case!E27/(1+J$7)^1.5+Base_Case!F27/(1+J$7)^2.5+Base_Case!G27/(1+J$7)^3.5+Base_Case!H27/(1+J$7)^4.5)+Base_Case!H14*$B10/(1+J$7)^4.5)-Assumptions!D35+Assumptions!D36)/Assumptions!D37,0) | K10: =IFERROR((((Base_Case!D27/(1+K$7)^0.5+Base_Case!E27/(1+K$7)^1.5+Base_Case!F27/(1+K$7)^2.5+Base_Case!G27/(1+K$7)^3.5+Base_Case!H27/(1+K$7)^4.5)+Base_Case!H14*$B10/(1+K$7)^4.5)-Assumptions!D35+Assumptions!D36)/Assumptions!D37,0)
B11: 18 | C11: =IFERROR((((Base_Case!D27/(1+C$7)^0.5+Base_Case!E27/(1+C$7)^1.5+Base_Case!F27/(1+C$7)^2.5+Base_Case!G27/(1+C$7)^3.5+Base_Case!H27/(1+C$7)^4.5)+Base_Case!H14*$B11/(1+C$7)^4.5)-Assumptions!D35+Assumptions!D36)/Assumptions!D37,0) | D11: =IFERROR((((Base_Case!D27/(1+D$7)^0.5+Base_Case!E27/(1+D$7)^1.5+Base_Case!F27/(1+D$7)^2.5+Base_Case!G27/(1+D$7)^3.5+Base_Case!H27/(1+D$7)^4.5)+Base_Case!H14*$B11/(1+D$7)^4.5)-Assumptions!D35+Assumptions!D36)/Assumptions!D37,0) | E11: =IFERROR((((Base_Case!D27/(1+E$7)^0.5+Base_Case!E27/(1+E$7)^1.5+Base_Case!F27/(1+E$7)^2.5+Base_Case!G27/(1+E$7)^3.5+Base_Case!H27/(1+E$7)^4.5)+Base_Case!H14*$B11/(1+E$7)^4.5)-Assumptions!D35+Assumptions!D36)/Assumptions!D37,0) | F11: =IFERROR((((Base_Case!D27/(1+F$7)^0.5+Base_Case!E27/(1+F$7)^1.5+Base_Case!F27/(1+F$7)^2.5+Base_Case!G27/(1+F$7)^3.5+Base_Case!H27/(1+F$7)^4.5)+Base_Case!H14*$B11/(1+F$7)^4.5)-Assumptions!D35+Assumptions!D36)/Assumptions!D37,0) | G11: =IFERROR((((Base_Case!D27/(1+G$7)^0.5+Base_Case!E27/(1+G$7)^1.5+Base_Case!F27/(1+G$7)^2.5+Base_Case!G27/(1+G$7)^3.5+Base_Case!H27/(1+G$7)^4.5)+Base_Case!H14*$B11/(1+G$7)^4.5)-Assumptions!D35+Assumptions!D36)/Assumptions!D37,0) | H11: =IFERROR((((Base_Case!D27/(1+H$7)^0.5+Base_Case!E27/(1+H$7)^1.5+Base_Case!F27/(1+H$7)^2.5+Base_Case!G27/(1+H$7)^3.5+Base_Case!H27/(1+H$7)^4.5)+Base_Case!H14*$B11/(1+H$7)^4.5)-Assumptions!D35+Assumptions!D36)/Assumptions!D37,0) | I11: =IFERROR((((Base_Case!D27/(1+I$7)^0.5+Base_Case!E27/(1+I$7)^1.5+Base_Case!F27/(1+I$7)^2.5+Base_Case!G27/(1+I$7)^3.5+Base_Case!H27/(1+I$7)^4.5)+Base_Case!H14*$B11/(1+I$7)^4.5)-Assumptions!D35+Assumptions!D36)/Assumptions!D37,0) | J11: =IFERROR((((Base_Case!D27/(1+J$7)^0.5+Base_Case!E27/(1+J$7)^1.5+Base_Case!F27/(1+J$7)^2.5+Base_Case!G27/(1+J$7)^3.5+Base_Case!H27/(1+J$7)^4.5)+Base_Case!H14*$B11/(1+J$7)^4.5)-Assumptions!D35+Assumptions!D36)/Assumptions!D37,0) | K11: =IFERROR((((Base_Case!D27/(1+K$7)^0.5+Base_Case!E27/(1+K$7)^1.5+Base_Case!F27/(1+K$7)^2.5+Base_Case!G27/(1+K$7)^3.5+Base_Case!H27/(1+K$7)^4.5)+Base_Case!H14*$B11/(1+K$7)^4.5)-Assumptions!D35+Assumptions!D36)/Assumptions!D37,0)
B12: 20 | C12: =IFERROR((((Base_Case!D27/(1+C$7)^0.5+Base_Case!E27/(1+C$7)^1.5+Base_Case!F27/(1+C$7)^2.5+Base_Case!G27/(1+C$7)^3.5+Base_Case!H27/(1+C$7)^4.5)+Base_Case!H14*$B12/(1+C$7)^4.5)-Assumptions!D35+Assumptions!D36)/Assumptions!D37,0) | D12: =IFERROR((((Base_Case!D27/(1+D$7)^0.5+Base_Case!E27/(1+D$7)^1.5+Base_Case!F27/(1+D$7)^2.5+Base_Case!G27/(1+D$7)^3.5+Base_Case!H27/(1+D$7)^4.5)+Base_Case!H14*$B12/(1+D$7)^4.5)-Assumptions!D35+Assumptions!D36)/Assumptions!D37,0) | E12: =IFERROR((((Base_Case!D27/(1+E$7)^0.5+Base_Case!E27/(1+E$7)^1.5+Base_Case!F27/(1+E$7)^2.5+Base_Case!G27/(1+E$7)^3.5+Base_Case!H27/(1+E$7)^4.5)+Base_Case!H14*$B12/(1+E$7)^4.5)-Assumptions!D35+Assumptions!D36)/Assumptions!D37,0) | F12: =IFERROR((((Base_Case!D27/(1+F$7)^0.5+Base_Case!E27/(1+F$7)^1.5+Base_Case!F27/(1+F$7)^2.5+Base_Case!G27/(1+F$7)^3.5+Base_Case!H27/(1+F$7)^4.5)+Base_Case!H14*$B12/(1+F$7)^4.5)-Assumptions!D35+Assumptions!D36)/Assumptions!D37,0) | G12: =IFERROR((((Base_Case!D27/(1+G$7)^0.5+Base_Case!E27/(1+G$7)^1.5+Base_Case!F27/(1+G$7)^2.5+Base_Case!G27/(1+G$7)^3.5+Base_Case!H27/(1+G$7)^4.5)+Base_Case!H14*$B12/(1+G$7)^4.5)-Assumptions!D35+Assumptions!D36)/Assumptions!D37,0) | H12: =IFERROR((((Base_Case!D27/(1+H$7)^0.5+Base_Case!E27/(1+H$7)^1.5+Base_Case!F27/(1+H$7)^2.5+Base_Case!G27/(1+H$7)^3.5+Base_Case!H27/(1+H$7)^4.5)+Base_Case!H14*$B12/(1+H$7)^4.5)-Assumptions!D35+Assumptions!D36)/Assumptions!D37,0) | I12: =IFERROR((((Base_Case!D27/(1+I$7)^0.5+Base_Case!E27/(1+I$7)^1.5+Base_Case!F27/(1+I$7)^2.5+Base_Case!G27/(1+I$7)^3.5+Base_Case!H27/(1+I$7)^4.5)+Base_Case!H14*$B12/(1+I$7)^4.5)-Assumptions!D35+Assumptions!D36)/Assumptions!D37,0) | J12: =IFERROR((((Base_Case!D27/(1+J$7)^0.5+Base_Case!E27/(1+J$7)^1.5+Base_Case!F27/(1+J$7)^2.5+Base_Case!G27/(1+J$7)^3.5+Base_Case!H27/(1+J$7)^4.5)+Base_Case!H14*$B12/(1+J$7)^4.5)-Assumptions!D35+Assumptions!D36)/Assumptions!D37,0) | K12: =IFERROR((((Base_Case!D27/(1+K$7)^0.5+Base_Case!E27/(1+K$7)^1.5+Base_Case!F27/(1+K$7)^2.5+Base_Case!G27/(1+K$7)^3.5+Base_Case!H27/(1+K$7)^4.5)+Base_Case!H14*$B12/(1+K$7)^4.5)-Assumptions!D35+Assumptions!D36)/Assumptions!D37,0)
B13: 22 | C13: =IFERROR((((Base_Case!D27/(1+C$7)^0.5+Base_Case!E27/(1+C$7)^1.5+Base_Case!F27/(1+C$7)^2.5+Base_Case!G27/(1+C$7)^3.5+Base_Case!H27/(1+C$7)^4.5)+Base_Case!H14*$B13/(1+C$7)^4.5)-Assumptions!D35+Assumptions!D36)/Assumptions!D37,0) | D13: =IFERROR((((Base_Case!D27/(1+D$7)^0.5+Base_Case!E27/(1+D$7)^1.5+Base_Case!F27/(1+D$7)^2.5+Base_Case!G27/(1+D$7)^3.5+Base_Case!H27/(1+D$7)^4.5)+Base_Case!H14*$B13/(1+D$7)^4.5)-Assumptions!D35+Assumptions!D36)/Assumptions!D37,0) | E13: =IFERROR((((Base_Case!D27/(1+E$7)^0.5+Base_Case!E27/(1+E$7)^1.5+Base_Case!F27/(1+E$7)^2.5+Base_Case!G27/(1+E$7)^3.5+Base_Case!H27/(1+E$7)^4.5)+Base_Case!H14*$B13/(1+E$7)^4.5)-Assumptions!D35+Assumptions!D36)/Assumptions!D37,0) | F13: =IFERROR((((Base_Case!D27/(1+F$7)^0.5+Base_Case!E27/(1+F$7)^1.5+Base_Case!F27/(1+F$7)^2.5+Base_Case!G27/(1+F$7)^3.5+Base_Case!H27/(1+F$7)^4.5)+Base_Case!H14*$B13/(1+F$7)^4.5)-Assumptions!D35+Assumptions!D36)/Assumptions!D37,0) | G13: =IFERROR((((Base_Case!D27/(1+G$7)^0.5+Base_Case!E27/(1+G$7)^1.5+Base_Case!F27/(1+G$7)^2.5+Base_Case!G27/(1+G$7)^3.5+Base_Case!H27/(1+G$7)^4.5)+Base_Case!H14*$B13/(1+G$7)^4.5)-Assumptions!D35+Assumptions!D36)/Assumptions!D37,0) | H13: =IFERROR((((Base_Case!D27/(1+H$7)^0.5+Base_Case!E27/(1+H$7)^1.5+Base_Case!F27/(1+H$7)^2.5+Base_Case!G27/(1+H$7)^3.5+Base_Case!H27/(1+H$7)^4.5)+Base_Case!H14*$B13/(1+H$7)^4.5)-Assumptions!D35+Assumptions!D36)/Assumptions!D37,0) | I13: =IFERROR((((Base_Case!D27/(1+I$7)^0.5+Base_Case!E27/(1+I$7)^1.5+Base_Case!F27/(1+I$7)^2.5+Base_Case!G27/(1+I$7)^3.5+Base_Case!H27/(1+I$7)^4.5)+Base_Case!H14*$B13/(1+I$7)^4.5)-Assumptions!D35+Assumptions!D36)/Assumptions!D37,0) | J13: =IFERROR((((Base_Case!D27/(1+J$7)^0.5+Base_Case!E27/(1+J$7)^1.5+Base_Case!F27/(1+J$7)^2.5+Base_Case!G27/(1+J$7)^3.5+Base_Case!H27/(1+J$7)^4.5)+Base_Case!H14*$B13/(1+J$7)^4.5)-Assumptions!D35+Assumptions!D36)/Assumptions!D37,0) | K13: =IFERROR((((Base_Case!D27/(1+K$7)^0.5+Base_Case!E27/(1+K$7)^1.5+Base_Case!F27/(1+K$7)^2.5+Base_Case!G27/(1+K$7)^3.5+Base_Case!H27/(1+K$7)^4.5)+Base_Case!H14*$B13/(1+K$7)^4.5)-Assumptions!D35+Assumptions!D36)/Assumptions!D37,0)
B14: 24 | C14: =IFERROR((((Base_Case!D27/(1+C$7)^0.5+Base_Case!E27/(1+C$7)^1.5+Base_Case!F27/(1+C$7)^2.5+Base_Case!G27/(1+C$7)^3.5+Base_Case!H27/(1+C$7)^4.5)+Base_Case!H14*$B14/(1+C$7)^4.5)-Assumptions!D35+Assumptions!D36)/Assumptions!D37,0) | D14: =IFERROR((((Base_Case!D27/(1+D$7)^0.5+Base_Case!E27/(1+D$7)^1.5+Base_Case!F27/(1+D$7)^2.5+Base_Case!G27/(1+D$7)^3.5+Base_Case!H27/(1+D$7)^4.5)+Base_Case!H14*$B14/(1+D$7)^4.5)-Assumptions!D35+Assumptions!D36)/Assumptions!D37,0) | E14: =IFERROR((((Base_Case!D27/(1+E$7)^0.5+Base_Case!E27/(1+E$7)^1.5+Base_Case!F27/(1+E$7)^2.5+Base_Case!G27/(1+E$7)^3.5+Base_Case!H27/(1+E$7)^4.5)+Base_Case!H14*$B14/(1+E$7)^4.5)-Assumptions!D35+Assumptions!D36)/Assumptions!D37,0) | F14: =IFERROR((((Base_Case!D27/(1+F$7)^0.5+Base_Case!E27/(1+F$7)^1.5+Base_Case!F27/(1+F$7)^2.5+Base_Case!G27/(1+F$7)^3.5+Base_Case!H27/(1+F$7)^4.5)+Base_Case!H14*$B14/(1+F$7)^4.5)-Assumptions!D35+Assumptions!D36)/Assumptions!D37,0) | G14: =IFERROR((((Base_Case!D27/(1+G$7)^0.5+Base_Case!E27/(1+G$7)^1.5+Base_Case!F27/(1+G$7)^2.5+Base_Case!G27/(1+G$7)^3.5+Base_Case!H27/(1+G$7)^4.5)+Base_Case!H14*$B14/(1+G$7)^4.5)-Assumptions!D35+Assumptions!D36)/Assumptions!D37,0) | H14: =IFERROR((((Base_Case!D27/(1+H$7)^0.5+Base_Case!E27/(1+H$7)^1.5+Base_Case!F27/(1+H$7)^2.5+Base_Case!G27/(1+H$7)^3.5+Base_Case!H27/(1+H$7)^4.5)+Base_Case!H14*$B14/(1+H$7)^4.5)-Assumptions!D35+Assumptions!D36)/Assumptions!D37,0) | I14: =IFERROR((((Base_Case!D27/(1+I$7)^0.5+Base_Case!E27/(1+I$7)^1.5+Base_Case!F27/(1+I$7)^2.5+Base_Case!G27/(1+I$7)^3.5+Base_Case!H27/(1+I$7)^4.5)+Base_Case!H14*$B14/(1+I$7)^4.5)-Assumptions!D35+Assumptions!D36)/Assumptions!D37,0) | J14: =IFERROR((((Base_Case!D27/(1+J$7)^0.5+Base_Case!E27/(1+J$7)^1.5+Base_Case!F27/(1+J$7)^2.5+Base_Case!G27/(1+J$7)^3.5+Base_Case!H27/(1+J$7)^4.5)+Base_Case!H14*$B14/(1+J$7)^4.5)-Assumptions!D35+Assumptions!D36)/Assumptions!D37,0) | K14: =IFERROR((((Base_Case!D27/(1+K$7)^0.5+Base_Case!E27/(1+K$7)^1.5+Base_Case!F27/(1+K$7)^2.5+Base_Case!G27/(1+K$7)^3.5+Base_Case!H27/(1+K$7)^4.5)+Base_Case!H14*$B14/(1+K$7)^4.5)-Assumptions!D35+Assumptions!D36)/Assumptions!D37,0)
B15: 26 | C15: =IFERROR((((Base_Case!D27/(1+C$7)^0.5+Base_Case!E27/(1+C$7)^1.5+Base_Case!F27/(1+C$7)^2.5+Base_Case!G27/(1+C$7)^3.5+Base_Case!H27/(1+C$7)^4.5)+Base_Case!H14*$B15/(1+C$7)^4.5)-Assumptions!D35+Assumptions!D36)/Assumptions!D37,0) | D15: =IFERROR((((Base_Case!D27/(1+D$7)^0.5+Base_Case!E27/(1+D$7)^1.5+Base_Case!F27/(1+D$7)^2.5+Base_Case!G27/(1+D$7)^3.5+Base_Case!H27/(1+D$7)^4.5)+Base_Case!H14*$B15/(1+D$7)^4.5)-Assumptions!D35+Assumptions!D36)/Assumptions!D37,0) | E15: =IFERROR((((Base_Case!D27/(1+E$7)^0.5+Base_Case!E27/(1+E$7)^1.5+Base_Case!F27/(1+E$7)^2.5+Base_Case!G27/(1+E$7)^3.5+Base_Case!H27/(1+E$7)^4.5)+Base_Case!H14*$B15/(1+E$7)^4.5)-Assumptions!D35+Assumptions!D36)/Assumptions!D37,0) | F15: =IFERROR((((Base_Case!D27/(1+F$7)^0.5+Base_Case!E27/(1+F$7)^1.5+Base_Case!F27/(1+F$7)^2.5+Base_Case!G27/(1+F$7)^3.5+Base_Case!H27/(1+F$7)^4.5)+Base_Case!H14*$B15/(1+F$7)^4.5)-Assumptions!D35+Assumptions!D36)/Assumptions!D37,0) | G15: =IFERROR((((Base_Case!D27/(1+G$7)^0.5+Base_Case!E27/(1+G$7)^1.5+Base_Case!F27/(1+G$7)^2.5+Base_Case!G27/(1+G$7)^3.5+Base_Case!H27/(1+G$7)^4.5)+Base_Case!H14*$B15/(1+G$7)^4.5)-Assumptions!D35+Assumptions!D36)/Assumptions!D37,0) | H15: =IFERROR((((Base_Case!D27/(1+H$7)^0.5+Base_Case!E27/(1+H$7)^1.5+Base_Case!F27/(1+H$7)^2.5+Base_Case!G27/(1+H$7)^3.5+Base_Case!H27/(1+H$7)^4.5)+Base_Case!H14*$B15/(1+H$7)^4.5)-Assumptions!D35+Assumptions!D36)/Assumptions!D37,0) | I15: =IFERROR((((Base_Case!D27/(1+I$7)^0.5+Base_Case!E27/(1+I$7)^1.5+Base_Case!F27/(1+I$7)^2.5+Base_Case!G27/(1+I$7)^3.5+Base_Case!H27/(1+I$7)^4.5)+Base_Case!H14*$B15/(1+I$7)^4.5)-Assumptions!D35+Assumptions!D36)/Assumptions!D37,0) | J15: =IFERROR((((Base_Case!D27/(1+J$7)^0.5+Base_Case!E27/(1+J$7)^1.5+Base_Case!F27/(1+J$7)^2.5+Base_Case!G27/(1+J$7)^3.5+Base_Case!H27/(1+J$7)^4.5)+Base_Case!H14*$B15/(1+J$7)^4.5)-Assumptions!D35+Assumptions!D36)/Assumptions!D37,0) | K15: =IFERROR((((Base_Case!D27/(1+K$7)^0.5+Base_Case!E27/(1+K$7)^1.5+Base_Case!F27/(1+K$7)^2.5+Base_Case!G27/(1+K$7)^3.5+Base_Case!H27/(1+K$7)^4.5)+Base_Case!H14*$B15/(1+K$7)^4.5)-Assumptions!D35+Assumptions!D36)/Assumptions!D37,0)
